Workbook

Sheet Notes
A1: Refrigeration Cycle - P-h Diagram Data and Verification
A3: Source: DWSIM 10.2, propane, Peng-Robinson property package, basis 1 mol/s
A5: Sheet guide
A6: Ph Diagram Data Saturation dome (bubble + dew) and the four cycle states. Chart is on this sheet.
A7: Cycle States The four thermodynamic states, from the DWSIM stream report.
A8: Verification Duties recomputed by hand from mass flow x enthalpy change, against DWSIM.
A9: Raw Envelope Data Original pasted export, unmodified.
A10: DWSIM Report Original pasted report, unmodified.
A12: Cleaning applied to the raw envelope export
A13: 1. The export contained five stacked copies, one per stream. All five were verified byte-identical
A14: (every stream is pure propane), so only one copy is retained.
A15: 2. The bubble point curve padded its last hundreds of rows by repeating the critical point. Those were removed.
... A18: 5. Unused envelope columns (entropy, volume, hydrate, Widom, SLE) dropped.

Sheet Ph Diagram Data
A1: Bubble h (kJ/kg) | B1: Bubble P (Pa) | C1: Bubble P (bar) | E1: Dew h (kJ/kg) | F1: Dew P (Pa) | G1: Dew P (bar) | I1: State | J1: Cycle h (kJ/kg) | K1: Cycle P (Pa) | L1: Cycle P (bar)
A2: -657.798 | B2: 1589.06 | C2: =B2/100000 -> 0.0158906 | E2: -107.247 | F2: 101325 | G2: =F2/100000 -> 1.01325 | I2: 1 | J2: -80.0775 | K2: 245000 | L2: =K2/100000 -> 2.45
A3: -656.001 | B3: 1742.91 | C3: =B3/100000 -> 0.0174291 | E3: -100.948 | F3: 126325 | G3: =F3/100000 -> 1.26325 | I3: 2 | J3: 15.2325 | K3: 1250000 | L3: =K3/100000 -> 12.5
A4: -654.2 | B4: 1909.29 | C4: =B4/100000 -> 0.0190929 | E4: -95.554 | F4: 151325 | G4: =F4/100000 -> 1.51325 | I4: 3 | J4: -346.191 | K4: 1250000 | L4: =K4/100000 -> 12.5
A5: -652.394 | B5: 2089.02 | C5: =B5/100000 -> 0.0208902 | E5: -94.3195 | F5: 157553 | G5: =F5/100000 -> 1.57553 | I5: 4 | J5: -346.191 | K5: 245000 | L5: =K5/100000 -> 2.45
A6: -650.584 | B6: 2282.96 | C6: =B6/100000 -> 0.0228296 | E6: -93.0855 | F6: 163977 | G6: =F6/100000 -> 1.63977 | I6: 1 (close) | J6: -80.0775 | K6: 245000 | L6: =K6/100000 -> 2.45
A7: -648.77 | B7: 2491.98 | C7: =B7/100000 -> 0.0249198 | E7: -91.8522 | F7: 170599 | G7: =F7/100000 -> 1.70599
A8: -646.951 | B8: 2717.03 | C8: =B8/100000 -> 0.0271703 | E8: -90.6195 | F8: 177426 | G8: =F8/100000 -> 1.77426
A9: -645.127 | B9: 2959.06 | C9: =B9/100000 -> 0.0295906 | E9: -89.3877 | F9: 184459 | G9: =F9/100000 -> 1.84459
A10: -643.299 | B10: 3219.11 | C10: =B10/100000 -> 0.0321911 | E10: -88.1568 | F10: 191704 | G10: =F10/100000 -> 1.91704
A11: -641.467 | B11: 3498.21 | C11: =B11/100000 -> 0.0349821 | E11: -86.9268 | F11: 199164 | G11: =F11/100000 -> 1.99164
A12: -639.63 | B12: 3797.46 | C12: =B12/100000 -> 0.0379746 | E12: -85.6979 | F12: 206844 | G12: =F12/100000 -> 2.06844
A13: -637.788 | B13: 4118.01 | C13: =B13/100000 -> 0.0411801 | E13: -84.4702 | F13: 214747 | G13: =F13/100000 -> 2.14747
A14: -635.941 | B14: 4461.03 | C14: =B14/100000 -> 0.0446103 | E14: -83.2437 | F14: 222879 | G14: =F14/100000 -> 2.22879
A15: -634.09 | B15: 4827.76 | C15: =B15/100000 -> 0.0482776 | E15: -82.0186 | F15: 231242 | G15: =F15/100000 -> 2.31242
A16: -632.234 | B16: 5219.47 | C16: =B16/100000 -> 0.0521947 | E16: -80.795 | F16: 239841 | G16: =F16/100000 -> 2.39841
A17: -630.373 | B17: 5637.48 | C17: =B17/100000 -> 0.0563748 | E17: -79.5728 | F17: 248681 | G17: =F17/100000 -> 2.48681
A18: -628.507 | B18: 6083.15 | C18: =B18/100000 -> 0.0608315 | E18: -78.3523 | F18: 257765 | G18: =F18/100000 -> 2.57765
... A134: -365.051 | B134: 966696 | C134: =B134/100000 -> 9.66696 | E134: -12.3729 | F134: 4209750 | G134: =F134/100000 -> 42.0975
A135: -362.209 | B135: 991392 | C135: =B135/100000 -> 9.91392
A136: -359.351 | B136: 1016540 | C136: =B136/100000 -> 10.1654
A137: -356.479 | B137: 1042150 | C137: =B137/100000 -> 10.4215
A138: -353.592 | B138: 1068220 | C138: =B138/100000 -> 10.6822
A139: -350.689 | B139: 1094760 | C139: =B139/100000 -> 10.9476
A140: -347.771 | B140: 1121770 | C140: =B140/100000 -> 11.2177
A141: -344.837 | B141: 1149260 | C141: =B141/100000 -> 11.4926
A142: -341.887 | B142: 1177230 | C142: =B142/100000 -> 11.7723
A143: -338.92 | B143: 1205690 | C143: =B143/100000 -> 12.0569
A144: -335.937 | B144: 1234640 | C144: =B144/100000 -> 12.3464
A145: -332.936 | B145: 1264080 | C145: =B145/100000 -> 12.6408
A146: -329.918 | B146: 1294030 | C146: =B146/100000 -> 12.9403
... A218: -11.1995 | B218: 4169160 | C218: =B218/100000 -> 41.6916

Sheet Cycle States
A1: State | B1: Location | C1: T (K) | D1: P (Pa) | E1: P (bar) | F1: h (kJ/kg) | G1: s (kJ/kg.K)
A2: 1 | B2: Evaporator out / compressor in | C2: 252.995 | D2: 245000 | E2: =D2/100000 -> 2.45 | F2: -80.0775 | G2: -0.447798
A3: 2 | B3: Compressor out / condenser in | C3: 325.138 | D3: 1250000 | E3: =D3/100000 -> 12.5 | F3: 15.2325 | G3: -0.388308
A4: 3 | B4: Condenser out / valve in | C4: 305 | D4: 1250000 | E4: =D4/100000 -> 12.5 | F4: -346.191 | G4: -1.55496
A5: 4 | B5: Valve out / evaporator in | C5: 252.995 | D5: 245000 | E5: =D5/100000 -> 2.45 | F5: -346.191 | G5: -1.49871
A6: 5 | B6: Evaporator out (closes to 1) | C6: 253 | D6: 245000 | E6: =D6/100000 -> 2.45 | F6: -80.0691 | G6: -0.447765
A8: States 1 and 5 are the same point; 5 is listed to show cycle closure (0.005 K apart).
A9: h3 = h4 exactly: the expansion valve is isenthalpic.

Sheet Verification
A1: Energy Balance Verification
A3: Mass flow (kg/s) | B3: 0.0440956 | C3: Basis: 1 mol/s propane
A5: Component | B5: h in (kJ/kg) | C5: h out (kJ/kg) | D5: dh (kJ/kg) | E5: Hand (kW) | F5: DWSIM (kW) | G5: Diff (%)
A6: Compressor | B6: ='Cycle States'!F2 -> -80.0775 | C6: ='Cycle States'!F3 -> 15.2325 | D6: =C6-B6 -> 95.31 | E6: =ABS($B$3*D6) -> 4.2027516 | F6: 4.20275 | G6: =IF(F6=0,"",ABS(E6-F6)/F6*100) -> 3.8926893e-05
A7: Condenser | B7: ='Cycle States'!F3 -> 15.2325 | C7: ='Cycle States'!F4 -> -346.191 | D7: =C7-B7 -> -361.4235 | E7: =ABS($B$3*D7) -> 15.937186 | F7: 15.9372 | G7: =IF(F7=0,"",ABS(E7-F7)/F7*100) -> 8.7301408e-05
A8: Evaporator | B8: ='Cycle States'!F5 -> -346.191 | C8: ='Cycle States'!F6 -> -80.0691 | D8: =C8-B8 -> 266.1219 | E8: =ABS($B$3*D8) -> 11.734805 | F8: 11.7348 | G8: =IF(F8=0,"",ABS(E8-F8)/F8*100) -> 4.136108e-05
A11: Checks
A12: COP = Q_evap / W_comp | B12: =E8/E6 -> 2.7921719 | C12: Tutorial expects 2 - 7
A13: Carnot COP = T_L / (T_H - T_L) | B13: =253/(305-253) -> 4.8653846 | C13: Ideal limit between 253 K and 305 K
A14: Second-law efficiency (%) | B14: =B12/B13*100 -> 57.388513 | C14: COP as a fraction of Carnot
A15: Energy balance: Q_evap + W (kW) | B15: =E8+E6 -> 15.937556 | C15: Should equal condenser duty
A16: Condenser duty (kW) | B16: =E7 -> 15.937186
A17: Balance closure error (%) | B17: =ABS(B15-B16)/B16*100 -> 0.0023241433 | C17: Tutorial allows 0.5%
A18: Cycle closure: T5 - T1 (K) | B18: ='Cycle States'!C6-'Cycle States'!C2 -> 0.005 | C18: Should be near zero

Sheet Raw Envelope Data
A1: Tb (K) | B1: Pb (Pa) | C1: Hb (kJ/kg) | D1: Sb (kJ/[kg.K]) | E1: Vb (m3/mol) | F1: Td (K) | G1: Pd (Pa) | H1: Hd (kJ/kg) | I1: Sd (kJ/[kg.K]) | J1: Vd (m3/mol) | K1: Test (K) | L1: Pest (Pa) | M1: TQ (K) | N1: PQ (Pa) | O1: TPIP (K) | P1: PPIP (Pa) | Q1: THsI (K) | R1: PHsI (Pa) | S1: THsII (K) | T1: PHsII (Pa) | U1: TDFW (K) | V1: PDFW (Pa) | W1: HDFW (kJ/kg) | X1: SDFW (kJ/[kg.K]) | Y1: VDFW (m3/mol) | Z1: Tb1 (K) | AA1: Pb1 (Pa) | AB1: Hb1 (kJ/kg) | AC1: Sb1 (kJ/[kg.K]) | AD1: Vb1 (m3/mol) | AE1: Tb2 (K) | AF1: Pb2 (Pa) | AG1: Hb2 (kJ/kg) | AH1: Sb2 (kJ/[kg.K]) | AI1: Vb2 (m3/mol) | AJ1: SLE L T (K) | AK1: SLE L P (Pa) | AL1: SLE S T (K) | AM1: SLE S P (Pa) | AN1: Widom Cp T (K) | AO1: Widom Cp P (Pa) | AP1: Widom kT T (K) | AQ1: Widom kT P (Pa) | AR1: Widom Avg T (K) | AS1: Widom Avg P (Pa)
A2: 166.424 | B2: 1589.06 | C2: -657.798 | D2: -2.87638 | E2: 0.0676043 | F2: 230.945 | G2: 101325 | H2: -107.247 | I2: -0.401637 | J2: 18.3215 | K2: 0 | L2: 0 | O2: 0 | P2: 0
A3: 167.424 | B3: 1742.91 | C3: -656.001 | D3: -2.86562 | E3: 0.0677072 | F3: 236.042 | G3: 126325 | H3: -100.948 | I3: -0.414724 | J3: 14.925
A4: 168.424 | B4: 1909.29 | C4: -654.2 | D4: -2.8549 | E4: 0.0678105 | F4: 240.408 | G4: 151325 | H4: -95.554 | I4: -0.424683 | J4: 12.6131
A5: 169.424 | B5: 2089.02 | C5: -652.394 | D5: -2.84421 | E5: 0.0679144 | F5: 241.408 | G5: 157553 | H5: -94.3195 | I5: -0.426813 | J5: 12.147
A6: 170.424 | B6: 2282.96 | C6: -650.584 | D6: -2.83356 | E6: 0.0680189 | F6: 242.408 | G6: 163977 | H6: -93.0855 | I6: -0.428888 | J6: 11.7019
A7: 171.424 | B7: 2491.98 | C7: -648.77 | D7: -2.82295 | E7: 0.0681239 | F7: 243.408 | G7: 170599 | H7: -91.8522 | I7: -0.43091 | J7: 11.2767
A8: 172.424 | B8: 2717.03 | C8: -646.951 | D8: -2.81237 | E8: 0.0682294 | F8: 244.408 | G8: 177426 | H8: -90.6195 | I8: -0.43288 | J8: 10.8703
A9: 173.424 | B9: 2959.06 | C9: -645.127 | D9: -2.80183 | E9: 0.0683354 | F9: 245.408 | G9: 184459 | H9: -89.3877 | I9: -0.434799 | J9: 10.4818
A10: 174.424 | B10: 3219.11 | C10: -643.299 | D10: -2.79132 | E10: 0.0684421 | F10: 246.408 | G10: 191704 | H10: -88.1568 | I10: -0.436667 | J10: 10.1102
A11: 175.424 | B11: 3498.21 | C11: -641.467 | D11: -2.78085 | E11: 0.0685493 | F11: 247.408 | G11: 199164 | H11: -86.9268 | I11: -0.438487 | J11: 9.75469
A12: 176.424 | B12: 3797.46 | C12: -639.63 | D12: -2.77041 | E12: 0.068657 | F12: 248.408 | G12: 206844 | H12: -85.6979 | I12: -0.440259 | J12: 9.41442
A13: 177.424 | B13: 4118.01 | C13: -637.788 | D13: -2.76 | E13: 0.0687653 | F13: 249.408 | G13: 214747 | H13: -84.4702 | I13: -0.441983 | J13: 9.08862
A14: 178.424 | B14: 4461.03 | C14: -635.941 | D14: -2.74963 | E14: 0.0688742 | F14: 250.408 | G14: 222879 | H14: -83.2437 | I14: -0.443662 | J14: 8.77656
... A134: 298.424 | B134: 966696 | C134: -365.051 | D134: -1.61561 | E134: 0.0894712 | F134: 370.408 | G134: 4209750 | H134: -12.3729 | I134: -0.614852 | J134: 0.304268
A135: 299.424 | B135: 991392 | C135: -362.209 | D135: -1.60627 | E135: 0.0897621
A136: 300.424 | B136: 1016540 | C136: -359.351 | D136: -1.5969 | E136: 0.0900568
A137: 301.424 | B137: 1042150 | C137: -356.479 | D137: -1.58753 | E137: 0.0903557
A138: 302.424 | B138: 1068220 | C138: -353.592 | D138: -1.57814 | E138: 0.0906587
A139: 303.424 | B139: 1094760 | C139: -350.689 | D139: -1.56873 | E139: 0.090966
A140: 304.424 | B140: 1121770 | C140: -347.771 | D140: -1.55931 | E140: 0.0912777
A141: 305.424 | B141: 1149260 | C141: -344.837 | D141: -1.54986 | E141: 0.091594
A142: 306.424 | B142: 1177230 | C142: -341.887 | D142: -1.54041 | E142: 0.0919149
A143: 307.424 | B143: 1205690 | C143: -338.92 | D143: -1.53093 | E143: 0.0922406
A144: 308.424 | B144: 1234640 | C144: -335.937 | D144: -1.52143 | E144: 0.0925714
A145: 309.424 | B145: 1264080 | C145: -332.936 | D145: -1.51191 | E145: 0.0929072
A146: 310.424 | B146: 1294030 | C146: -329.918 | D146: -1.50237 | E146: 0.0932483
... A501: 369.83 | B501: 4169160 | C501: -11.1997 | D501: -0.610929 | E501: 0.186246
A503: 2_comp_out
A504: Tb (K) | B504: Pb (Pa) | C504: Hb (kJ/kg) | D504: Sb (kJ/[kg.K]) | E504: Vb (m3/mol) | F504: Td (K) | G504: Pd (Pa) | H504: Hd (kJ/kg) | I504: Sd (kJ/[kg.K]) | J504: Vd (m3/mol) | K504: Test (K) | L504: Pest (Pa) | M504: TQ (K) | N504: PQ (Pa) | O504: TPIP (K) | P504: PPIP (Pa) | Q504: THsI (K) | R504: PHsI (Pa) | S504: THsII (K) | T504: PHsII (Pa) | U504: TDFW (K) | V504: PDFW (Pa) | W504: HDFW (kJ/kg) | X504: SDFW (kJ/[kg.K]) | Y504: VDFW (m3/mol) | Z504: Tb1 (K) | AA504: Pb1 (Pa) | AB504: Hb1 (kJ/kg) | AC504: Sb1 (kJ/[kg.K]) | AD504: Vb1 (m3/mol) | AE504: Tb2 (K) | AF504: Pb2 (Pa) | AG504: Hb2 (kJ/kg) | AH504: Sb2 (kJ/[kg.K]) | AI504: Vb2 (m3/mol) | AJ504: SLE L T (K) | AK504: SLE L P (Pa) | AL504: SLE S T (K) | AM504: SLE S P (Pa) | AN504: Widom Cp T (K) | AO504: Widom Cp P (Pa) | AP504: Widom kT T (K) | AQ504: Widom kT P (Pa) | AR504: Widom Avg T (K) | AS504: Widom Avg P (Pa)
A505: 166.424 | B505: 1589.06 | C505: -657.798 | D505: -2.87638 | E505: 0.0676043 | F505: 230.945 | G505: 101325 | H505: -107.247 | I505: -0.401637 | J505: 18.3215 | K505: 0 | L505: 0 | O505: 0 | P505: 0
A506: 167.424 | B506: 1742.91 | C506: -656.001 | D506: -2.86562 | E506: 0.0677072 | F506: 236.042 | G506: 126325 | H506: -100.948 | I506: -0.414724 | J506: 14.925
A507: 168.424 | B507: 1909.29 | C507: -654.2 | D507: -2.8549 | E507: 0.0678105 | F507: 240.408 | G507: 151325 | H507: -95.554 | I507: -0.424683 | J507: 12.6131
A508: 169.424 | B508: 2089.02 | C508: -652.394 | D508: -2.84421 | E508: 0.0679144 | F508: 241.408 | G508: 157553 | H508: -94.3195 | I508: -0.426813 | J508: 12.147
A509: 170.424 | B509: 2282.96 | C509: -650.584 | D509: -2.83356 | E509: 0.0680189 | F509: 242.408 | G509: 163977 | H509: -93.0855 | I509: -0.428888 | J509: 11.7019
A510: 171.424 | B510: 2491.98 | C510: -648.77 | D510: -2.82295 | E510: 0.0681239 | F510: 243.408 | G510: 170599 | H510: -91.8522 | I510: -0.43091 | J510: 11.2767
A511: 172.424 | B511: 2717.03 | C511: -646.951 | D511: -2.81237 | E511: 0.0682294 | F511: 244.408 | G511: 177426 | H511: -90.6195 | I511: -0.43288 | J511: 10.8703
A512: 173.424 | B512: 2959.06 | C512: -645.127 | D512: -2.80183 | E512: 0.0683354 | F512: 245.408 | G512: 184459 | H512: -89.3877 | I512: -0.434799 | J512: 10.4818
A513: 174.424 | B513: 3219.11 | C513: -643.299 | D513: -2.79132 | E513: 0.0684421 | F513: 246.408 | G513: 191704 | H513: -88.1568 | I513: -0.436667 | J513: 10.1102
A514: 175.424 | B514: 3498.21 | C514: -641.467 | D514: -2.78085 | E514: 0.0685493 | F514: 247.408 | G514: 199164 | H514: -86.9268 | I514: -0.438487 | J514: 9.75469
...

Sheet DWSIM_Report
A1: Object: CD-1
A3: Flow Conductance | B3: 1 | C3: [kg/s]/[Pa^0.5]
A4: Volume | B4: 1 | C4: m3
A5: Minimum Pressure | B5: 101325 | C5: Pa
A6: Initialize using Inlet Stream | B6: -1
A7: Reset Content | B7: 0
A8: Ambient Temperature | B8: 298.15 | C8: K
A9: Ambient UA Product | B9: 0 | C9: W/[m2.K]
A10: Wall Thermal Mass | B10: 0
A11: Wall Temperature | B11: 298.15 | C11: K
A12: Pressure Drop | B12: 0 | C12: Pa
A13: Efficiency | B13: 100
A14: Outlet Temperature | B14: 305 | C14: K
A15: Heat Removed | B15: 15.9372 | C15: kW
A16: Outlet Molar Vapor Fraction | B16: 0
A17: Temperature Difference | B17: -20.138 | C17: K.
A19: Object: EV-1
A21: Flow Conductance | B21: 1 | C21: [kg/s]/[Pa^0.5]
A22: Volume | B22: 1 | C22: m3
A23: Minimum Pressure | B23: 101325 | C23: Pa
A24: Initialize using Inlet Stream | B24: -1
A25: Reset Content | B25: 0
A26: Ambient Temperature | B26: 298.15 | C26: K
A27: Ambient UA Product | B27: 0 | C27: W/[m2.K]
A28: Wall Thermal Mass | B28: 0
A29: Wall Temperature | B29: 298.15 | C29: K
A30: Pressure Drop | B30: 0 | C30: Pa
A31: Efficiency | B31: 100
A32: Outlet Temperature | B32: 253 | C32: K
A33: Heat Added | B33: 11.7348 | C33: kW
A34: Outlet Molar Vapor Fraction | B34: 1
A35: Temperature Difference | B35: 0.00542038 | C35: K.
A37: Object: C-1
A39: Flow Conductance | B39: 1 | C39: [kg/s]/[Pa^0.5]
A40: Volume | B40: 0.01 | C40: m3
A41: Minimum Pressure | B41: 101325 | C41: Pa
A42: Initialize using Inlet Stream | B42: -1
A43: Reset Content | B43: 0
A44: Rotational Inertia | B44: 0
A45: Current Speed | B45: 3000
...
